Workbook

Sheet README
B1: Lumora: business economics model
B2: Illustrative 36-month model for an 18+ creator-subscription platform. All figures are USD and are planning estimates, not quotes. Replace them with real vendor quotes as you get them.
B3: Not financial, legal or tax advice. Have an accountant and adult-industry counsel review before you raise money or launch.
B4: How to use
B5: 1. Yellow cells with blue text are inputs. Change them; every other number is a formula.
B6: 2. Pick a scenario on Assumptions (1 = Conservative, 2 = Base, 3 = Aggressive).
B7: 3. Edit headcount and salaries on Team, recurring costs on Fixed Costs, launch costs on Setup Costs.
B8: 4. Read results on Summary (yearly P&L, break-even, funding need, charts) and Unit Economics (where each $100 of fan spend goes).
B9: Tabs
B10: Summary: yearly P&L, key metrics and charts.
B11: Assumptions: scenario drivers, fees, other income, variable costs, tax, funding.
B12: Unit Economics: $100 of fan spend under 3 fee models, plus creator LTV / CAC.
... B47: All other costs are planning estimates (India-based core team, offshore entity). Replace with real quotes.

Sheet Summary
A1: Lumora: business economics summary
A2: ="Scenario: "&Assumptions!$C$4&" | All figures USD, planning estimates" -> Scenario: Base | All figures USD, planning estimates
A4: Yearly P&L | B4: Year 1 | C4: Year 2 | D4: Year 3 | F4: Key metrics | G4: Value
A5: Active creators (end of year) | B5: =INDEX(Projection!$C$8:$AL$8,1,12) -> 760.01237 | C5: =INDEX(Projection!$C$8:$AL$8,1,24) -> 1989.8287 | D5: =INDEX(Projection!$C$8:$AL$8,1,36) -> 3553.6778 | F5: Break-even month (first month EBITDA > 0) | G5: =IF(MIN(Projection!$C$48:$AL$48)=999,"Not within 36 months","Month "&MIN(Projection!$C$48:$AL$48)) -> Month 28
A6: Paying fans (end of year) | B6: =INDEX(Projection!$C$10:$AL$10,1,12) -> 15662.864 | C6: =INDEX(Projection!$C$10:$AL$10,1,24) -> 59694.86 | D6: =INDEX(Projection!$C$10:$AL$10,1,36) -> 106610.33 | F6: Lowest cash balance over 36 months | G6: =MIN(Projection!$C$53:$AL$53) -> -2321372.6
A7: Fan spend / GMV | B7: =SUMIF(Projection!$C$5:$AL$5,"Y1",Projection!$C$11:$AL$11) -> 1884647.6 | C7: =SUMIF(Projection!$C$5:$AL$5,"Y2",Projection!$C$11:$AL$11) -> 11189347 | D7: =SUMIF(Projection!$C$5:$AL$5,"Y3",Projection!$C$11:$AL$11) -> 25139817 | F7: Extra funding needed beyond starting capital | G7: =MAX(0,-G6) -> 2321372.6
A8: Net revenue | B8: =SUMIF(Projection!$C$5:$AL$5,"Y1",Projection!$C$21:$AL$21) -> 399047.84 | C8: =SUMIF(Projection!$C$5:$AL$5,"Y2",Projection!$C$21:$AL$21) -> 2322678.7 | D8: =SUMIF(Projection!$C$5:$AL$5,"Y3",Projection!$C$21:$AL$21) -> 5191204.5 | F8: Total capital needed (setup + peak burn) | G8: =Assumptions!$B$55-G6 -> 2571372.6
A9: Variable costs | B9: =SUMIF(Projection!$C$5:$AL$5,"Y1",Projection!$C$33:$AL$33) -> 288232.11 | C9: =SUMIF(Projection!$C$5:$AL$5,"Y2",Projection!$C$33:$AL$33) -> 1651305.4 | D9: =SUMIF(Projection!$C$5:$AL$5,"Y3",Projection!$C$33:$AL$33) -> 3676602.3 | F9: Monthly burn before revenue (month 1 fixed costs) | G9: =Projection!$C$42 -> 56347
A10: Contribution | B10: =SUMIF(Projection!$C$5:$AL$5,"Y1",Projection!$C$34:$AL$34) -> 110815.73 | C10: =SUMIF(Projection!$C$5:$AL$5,"Y2",Projection!$C$34:$AL$34) -> 671373.25 | D10: =SUMIF(Projection!$C$5:$AL$5,"Y3",Projection!$C$34:$AL$34) -> 1514602.3 | F10: One-time setup costs | G10: ='Setup Costs'!$B$17 -> 81206
A11: Fixed costs | B11: =SUMIF(Projection!$C$5:$AL$5,"Y1",Projection!$C$42:$AL$42) -> 766040.3 | C11: =SUMIF(Projection!$C$5:$AL$5,"Y2",Projection!$C$42:$AL$42) -> 1174714.4 | D11: =SUMIF(Projection!$C$5:$AL$5,"Y3",Projection!$C$42:$AL$42) -> 1370742.5 | F11: Month 36 GMV run-rate (annualized) | G11: =INDEX(Projection!$C$11:$AL$11,1,36)*12 -> 31983100
A12: EBITDA | B12: =SUMIF(Projection!$C$5:$AL$5,"Y1",Projection!$C$44:$AL$44) -> -655224.57 | C12: =SUMIF(Projection!$C$5:$AL$5,"Y2",Projection!$C$44:$AL$44) -> -503341.17 | D12: =SUMIF(Projection!$C$5:$AL$5,"Y3",Projection!$C$44:$AL$44) -> 143859.75 | F12: Month 36 net take rate (% of GMV) | G12: =INDEX(Projection!$C$36:$AL$36,1,36) -> 0.060258785
A13: Net income | B13: =SUMIF(Projection!$C$5:$AL$5,"Y1",Projection!$C$47:$AL$47) -> -655224.57 | C13: =SUMIF(Projection!$C$5:$AL$5,"Y2",Projection!$C$47:$AL$47) -> -503341.17 | D13: =SUMIF(Projection!$C$5:$AL$5,"Y3",Projection!$C$47:$AL$47) -> 102879.96 | F13: Month 36 EBITDA margin | G13: =INDEX(Projection!$C$45:$AL$45,1,36) -> 0.066124656
A14: Net cash flow | B14: =SUMIF(Projection!$C$5:$AL$5,"Y1",Projection!$C$52:$AL$52) -> -809212.81 | C14: =SUMIF(Projection!$C$5:$AL$5,"Y2",Projection!$C$52:$AL$52) -> -1077065.3 | D14: =SUMIF(Projection!$C$5:$AL$5,"Y3",Projection!$C$52:$AL$52) -> -603888.45 | F14: Creator LTV / CAC | G14: ='Unit Economics'!B26 -> 5.0215654
A15: Cash in bank (end of year) | B15: =INDEX(Projection!$C$53:$AL$53,1,12) -> -640418.81 | C15: =INDEX(Projection!$C$53:$AL$53,1,24) -> -1717484.1 | D15: =INDEX(Projection!$C$53:$AL$53,1,36) -> -2321372.6 | F15: Platform keeps per $100 fan spend (Model A) | G15: ='Unit Economics'!B15 -> 6.6166667
F16: Platform keeps per $100 fan spend (Model B) | G16: ='Unit Economics'!C15 -> 13.59
F18: Read Unit Economics before setting prices: processing fees decide most of your margin.

Sheet Assumptions
A1: Assumptions (edit yellow cells)
A2: Legend: yellow fill + blue text = input. Black = formula. Example: change B5 to 1 to see the conservative case.
A4: Scenario selected (1 = Conservative, 2 = Base, 3 = Aggressive) | B4: 2 | C4: =INDEX({"Conservative","Base","Aggressive"},1,B4) -> Base
A6: Scenario driver | B6: Live value | C6: Conservative | D6: Base | E6: Aggressive | F6: Unit / note
A7: New verified creators in month 1 | B7: =INDEX(C7:E7,1,$B$4) -> 40 | C7: 25 | D7: 40 | E7: 60 | F7: creators
A8: Growth in new creator sign-ups, months 1-12 | B8: =INDEX(C8:E8,1,$B$4) -> 0.12 | C8: 0.08 | D8: 0.12 | E8: 0.16 | F8: per month
A9: Growth in new creator sign-ups, months 13-36 | B9: =INDEX(C9:E9,1,$B$4) -> 0.04 | C9: 0.02 | D9: 0.04 | E9: 0.06 | F9: per month
A10: Active creator churn | B10: =INDEX(C10:E10,1,$B$4) -> 0.06 | C10: 0.08 | D10: 0.06 | E10: 0.045 | F10: per month
A11: Paying fans per active creator, month 1 | B11: =INDEX(C11:E11,1,$B$4) -> 12 | C11: 8 | D11: 12 | E11: 15 | F11: average incl. creators with no fans
A12: Paying fans per active creator, month 24 onward | B12: =INDEX(C12:E12,1,$B$4) -> 30 | C12: 20 | D12: 30 | E12: 40 | F12: ramps linearly from month 1
A13: Spend per paying fan per month (ARPPU) | B13: =INDEX(C13:E13,1,$B$4) -> 25 | C13: 20 | D13: 25 | E13: 30 | F13: USD, excl. VAT; all streams combined
A14: Cost to acquire one verified creator (CAC) | B14: =INDEX(C14:E14,1,$B$4) -> 150 | C14: 200 | D14: 150 | E14: 120 | F14: USD; ads, affiliates, onboarding incentives
A16: Pricing and fees | B16: Value | C16: Unit | F16: Note / source
A17: Platform commission on fan spend | B17: 0.2 | C17: % of GMV | F17: Creators keep the rest. Industry standard is 20%.
A18: Fan service fee added on top of price | B18: 0 | C18: % of GMV | F18: Optional. Set e.g. 8% to cover processing (see Unit Economics, Model B).
A19: Card processing rate | B19: 0.12 | C19: % of fan payment | F19: Adult processors ~10-15% (adults.dev, fanso.io). Use your contract rate.
A20: Card processing fixed fee per transaction | B20: 0 | C20: USD | F20: Set if your contract has a per-transaction fee.
A21: Average transaction size | B21: 15 | C21: USD | F21: Mix of subs, tips, unlocks.
A22: Chargeback rate | B22: 0.005 | C22: % of transactions | F22: Keep well under ~0.9-1% network monitoring thresholds.
A23: Fee per chargeback | B23: 25 | C23: USD | F23: Typical processor dispute fee; confirm in contract.
A24: Refunds | B24: 0.01 | C24: % of GMV | F24: Most refunds are reversed from creator balance.
A25: Share of refunds borne by platform | B25: 0.25 | C25: % of refunds | F25: Goodwill refunds, creator balance shortfalls.
A26: Referral share paid to referring creator | B26: 0.05 | C26: % of platform fee | F26: 12 months per referred creator.
A27: Share of GMV from referred creators | B27: 0.3 | C27: % of GMV
A28: Processor rolling reserve | B28: 0.1 | C28: % of fan payments | F28: Common for high-risk merchants; confirm in contract.
A29: Reserve holding period | B29: 6 | C29: months | F29: Released after this many months.
A30: Creator earnings hold before payout | B30: 7 | C30: days | F30: Absorbs refunds/chargebacks. Creator money, not yours.
A32: Other income streams | B32: Value | C32: Unit | F32: Note / source
A33: Instant payout fee | B33: 0.02 | C33: % of amount | F33: Free weekly payout stays free.
A34: Share of creator payouts taken instantly | B34: 0.1 | C34: %
A35: Creator Pro tools price | B35: 19 | C35: USD / month | F35: Analytics, automation, extra storage.
A36: Creator Pro adoption | B36: 0.08 | C36: % of active creators
A37: Agency / chatter seat price | B37: 29 | C37: USD / seat / month
A38: Agency seats per 100 active creators | B38: 10 | C38: seats
A39: Featured placement revenue per 100 active creators | B39: 150 | C39: USD / month | F39: SFW Explore placements, labelled Promoted.
A41: Variable costs | B41: Value | C41: Unit | F41: Note / source
A42: Bandwidth / video delivery per paying fan | B42: 0.1 | C42: USD / month | F42: CDN + HLS delivery; estimate.
A43: Storage + transcoding per active creator | B43: 1.5 | C43: USD / month | F43: Estimate.
A44: Automated moderation (classifiers, hash checks) per active creator | B44: 2 | C44: USD / month | F44: Estimate; depends on upload volume.
A45: Identity verification per new creator | B45: 2.5 | C45: USD | F45: ID + liveness incl. retries; get vendor quote.
...

Sheet Team
A1: Team plan (monthly cost per person, USD)
A2: Inputs in yellow. Costs assume an India-based team on contract; adjust for your hiring location.
A4: Role | B4: Headcount | C4: Monthly cost each | D4: Start month | E4: Monthly cost (full) | F4: Note
A5: Founder / CEO | B5: 1 | C5: 2000 | D5: 1 | E5: =B5*C5 -> 2000 | F5: Pay yourself something; it keeps the model honest.
A6: Full-stack engineers | B6: 3 | C6: 3000 | D6: 1 | E6: =B6*C6 -> 9000 | F6: Maintain platform, vendor integrations
A7: DevOps / SRE | B7: 1 | C7: 3000 | D7: 1 | E7: =B7*C7 -> 3000 | F7: Uptime, security, deploys
A8: Product designer | B8: 1 | C8: 2000 | D8: 1 | E8: =B8*C8 -> 2000
A9: QA engineer | B9: 1 | C9: 1500 | D9: 4 | E9: =B9*C9 -> 1500
A10: Trust & Safety lead | B10: 1 | C10: 2500 | D10: 1 | E10: =B10*C10 -> 2500 | F10: Owns moderation, legal reports
A11: Content moderators (24/7 rota) | B11: 5 | C11: 900 | D11: 1 | E11: =B11*C11 -> 4500 | F11: Minimum for round-the-clock P0 coverage
A12: Compliance & payments ops | B12: 1 | C12: 2500 | D12: 1 | E12: =B12*C12 -> 2500 | F12: KYC queue, processors, chargebacks
A13: Customer support agents | B13: 2 | C13: 800 | D13: 1 | E13: =B13*C13 -> 1600
A14: Creator partnerships & marketing | B14: 1 | C14: 2000 | D14: 1 | E14: =B14*C14 -> 2000 | F14: Recruits creators and agencies
A15: Engineers (second wave) | B15: 2 | C15: 3000 | D15: 13 | E15: =B15*C15 -> 6000
A16: Content moderators (second wave) | B16: 5 | C16: 900 | D16: 13 | E16: =B16*C16 -> 4500 | F16: Scale with uploads
A17: Support agents (second wave) | B17: 2 | C17: 800 | D17: 13 | E17: =B17*C17 -> 1600
A18: Finance manager | B18: 1 | C18: 2500 | D18: 13 | E18: =B18*C18 -> 2500 | F18: Reconciliations, tax filings
A19: Total at full build-out (before overhead) | B19: =SUM(B5:B18) -> 27 | E19: =SUM(E5:E18) -> 45200

Sheet Fixed Costs
A1: Monthly recurring costs excluding payroll (USD)
A2: Annual costs are divided by 12. All are estimates; replace with quotes.
A4: Category | B4: Item | C4: Monthly cost | D4: Note
A5: Infrastructure | B5: Cloud servers (API, web, workers) | C5: 600 | D5: Base load; variable delivery costs are on Assumptions
A6: Infrastructure | B6: Managed PostgreSQL + backups | C6: 300
A7: Infrastructure | B7: Redis / queues | C7: 100
A8: Infrastructure | B8: Object storage + CDN minimum commitment | C8: 200 | D8: Use an adult-friendly CDN
A9: Infrastructure | B9: Live streaming servers (base) | C9: 300 | D9: LiveKit self-hosted
A10: Infrastructure | B10: Monitoring, logging, error tracking | C10: 200
A11: Software | B11: Google Workspace (~15 seats) | C11: 110
A12: Software | B12: GitHub Team | C12: 60
A13: Software | B13: Help desk | C13: 150
A14: Software | B14: Transactional email | C14: 50
A15: Software | B15: Design tools | C15: 45
A16: Software | B16: Password manager | C16: 40
A17: Software | B17: Accounting software | C17: 50
A18: Compliance & legal | B18: Adult-industry legal retainer | C18: 2000 | D18: Policy updates, takedown disputes, contracts
A19: Compliance & legal | B19: Accountant & bookkeeping | C19: 800 | D19: Multi-jurisdiction VAT/GST filings
A20: Compliance & legal | B20: Contractor payroll / EOR fees | C20: 300
A21: Compliance & legal | B21: Anti-piracy / DMCA takedown service | C21: 500
A22: Compliance & legal | B22: Card-network high-risk registration (annual / 12) | C22: 170 | D22: Visa + Mastercard; confirm amount with processor
A23: Compliance & legal | B23: Annual penetration test (annual / 12) | C23: 1250
A24: Compliance & legal | B24: Insurance: cyber, E&O, D&O (annual / 12) | C24: 700 | D24: Adult businesses pay more; get quotes
A25: Compliance & legal | B25: Registered office / company secretary | C25: 150
A26: Compliance & legal | B26: KYC / moderation vendor minimum commitments | C26: 500 | D26: Many vendors have monthly minimums
A27: Compliance & legal | B27: Hash-matching / CSAM detection service | C27: 300
A28: Compliance & legal | B28: Business banking (high-risk friendly) | C28: 100
A29: Operations | B29: Coworking / office | C29: 500
A30: Operations | B30: Domains, SSL, misc | C30: 30
A31: Marketing | B31: SEO, content and social | C31: 2000 | D31: Creator acquisition spend is separate (CAC)
A32: Marketing | B32: Affiliate / referral program management | C32: 300
A33: Marketing | B33: Industry events & travel (annual / 12) | C33: 500
B34: Total monthly recurring (excl. payroll) | C34: =SUM(C5:C33) -> 12305
B36: Subtotals by category
B37: Infrastructure | C37: =SUMIF($A$5:$A$33,B37,$C$5:$C$33) -> 1700
B38: Software | C38: =SUMIF($A$5:$A$33,B38,$C$5:$C$33) -> 505
B39: Compliance & legal | C39: =SUMIF($A$5:$A$33,B39,$C$5:$C$33) -> 6770
B40: Operations | C40: =SUMIF($A$5:$A$33,B40,$C$5:$C$33) -> 530
B41: Marketing | C41: =SUMIF($A$5:$A$33,B41,$C$5:$C$33) -> 2800

Sheet Setup Costs
A1: One-time setup costs before / at launch (USD)
A3: Item | B3: Cost | C3: Note
A4: Company formation in an adult-workable jurisdiction + registered agent | B4: 1500 | C4: e.g. UK Ltd or US LLC; get counsel first
A5: Adult-industry counsel: ToS, creator & agency agreements, AUP, privacy, 2257, DMCA | B5: 15000
A6: Tax structuring advice (VAT/GST, cross-border, transfer pricing) | B6: 5000
A7: Trademark filings for "Lumora" (2-3 jurisdictions) | B7: 3000 | C7: Run clearance search first
A8: Brand identity and landing page imagery | B8: 3000
A9: Remaining engineering: real processor, KYC and moderation integrations; hardening | B9: 15000 | C9: Current build uses mock vendors
A10: Pre-launch penetration test | B10: 12000
A11: Processor and KYC vendor onboarding / setup fees | B11: 2500 | C11: Varies by vendor; some charge none
A12: DMCA agent designation (US Copyright Office) | B12: 6
A13: Domain, email, SSL setup | B13: 200
A14: Laptops and equipment | B14: 4000
A15: Launch marketing and creator seeding (first ~100 creators) | B15: 15000 | C15: Onboarding bonuses, content shoots, ads
A16: Legal and compliance contingency | B16: 5000
A17: Total one-time setup | B17: =SUM(B4:B16) -> 81206

Sheet Projection
A1: Monthly projection (USD)
A2: ="Scenario: "&Assumptions!$C$4 -> Scenario: Base
A3: Line item | C3: M1 | D3: M2 | E3: M3 | F3: M4 | G3: M5 | H3: M6 | I3: M7 | J3: M8 | K3: M9 | L3: M10 | M3: M11 | N3: M12 | O3: M13 | P3: M14 | Q3: M15 | R3: M16 | S3: M17 | T3: M18 | U3: M19 | V3: M20 | W3: M21 | X3: M22 | Y3: M23 | Z3: M24 | AA3: M25 | AB3: M26 | AC3: M27 | AD3: M28 | AE3: M29 | AF3: M30 | AG3: M31 | AH3: M32 | AI3: M33 | AJ3: M34 | AK3: M35 | AL3: M36
A4: Month | C4: 1 | D4: =C4+1 -> 2 | E4: =D4+1 -> 3 | F4: =E4+1 -> 4 | G4: =F4+1 -> 5 | H4: =G4+1 -> 6 | I4: =H4+1 -> 7 | J4: =I4+1 -> 8 | K4: =J4+1 -> 9 | ... AL4: =AK4+1 -> 36
A5: Year | C5: ="Y"&ROUNDUP(C4/12,0) -> Y1 | D5: ="Y"&ROUNDUP(D4/12,0) -> Y1 | E5: ="Y"&ROUNDUP(E4/12,0) -> Y1 | F5: ="Y"&ROUNDUP(F4/12,0) -> Y1 | G5: ="Y"&ROUNDUP(G4/12,0) -> Y1 | H5: ="Y"&ROUNDUP(H4/12,0) -> Y1 | I5: ="Y"&ROUNDUP(I4/12,0) -> Y1 | J5: ="Y"&ROUNDUP(J4/12,0) -> Y1 | ... AL5: ="Y"&ROUNDUP(AL4/12,0) -> Y3
A6: Creators and fans
A7: New verified creators | C7: =IF(C4<=12,Assumptions!$B$7*(1+Assumptions!$B$8)^(C4-1),Assumptions!$B$7*(1+Assumptions!$B$8)^11*(1+Assumptions!$B$9)^(C4-12)) -> 40 | D7: =IF(D4<=12,Assumptions!$B$7*(1+Assumptions!$B$8)^(D4-1),Assumptions!$B$7*(1+Assumptions!$B$8)^11*(1+Assumptions!$B$9)^(D4-12)) -> 44.8 | E7: =IF(E4<=12,Assumptions!$B$7*(1+Assumptions!$B$8)^(E4-1),Assumptions!$B$7*(1+Assumptions!$B$8)^11*(1+Assumptions!$B$9)^(E4-12)) -> 50.176 | F7: =IF(F4<=12,Assumptions!$B$7*(1+Assumptions!$B$8)^(F4-1),Assumptions!$B$7*(1+Assumptions!$B$8)^11*(1+Assumptions!$B$9)^(F4-12)) -> 56.19712 | G7: =IF(G4<=12,Assumptions!$B$7*(1+Assumptions!$B$8)^(G4-1),Assumptions!$B$7*(1+Assumptions!$B$8)^11*(1+Assumptions!$B$9)^(G4-12)) -> 62.940774 | H7: =IF(H4<=12,Assumptions!$B$7*(1+Assumptions!$B$8)^(H4-1),Assumptions!$B$7*(1+Assumptions!$B$8)^11*(1+Assumptions!$B$9)^(H4-12)) -> 70.493667 | I7: =IF(I4<=12,Assumptions!$B$7*(1+Assumptions!$B$8)^(I4-1),Assumptions!$B$7*(1+Assumptions!$B$8)^11*(1+Assumptions!$B$9)^(I4-12)) -> 78.952907 | J7: =IF(J4<=12,Assumptions!$B$7*(1+Assumptions!$B$8)^(J4-1),Assumptions!$B$7*(1+Assumptions!$B$8)^11*(1+Assumptions!$B$9)^(J4-12)) -> 88.427256 | ... AL7: =IF(AL4<=12,Assumptions!$B$7*(1+Assumptions!$B$8)^(AL4-1),Assumptions!$B$7*(1+Assumptions!$B$8)^11*(1+Assumptions!$B$9)^(AL4-12)) -> 356.66327
A8: Active creators (end of month) | C8: =C7 -> 40 | D8: =C8*(1-Assumptions!$B$10)+D7 -> 82.4 | E8: =D8*(1-Assumptions!$B$10)+E7 -> 127.632 | F8: =E8*(1-Assumptions!$B$10)+F7 -> 176.1712 | G8: =F8*(1-Assumptions!$B$10)+G7 -> 228.5417 | H8: =G8*(1-Assumptions!$B$10)+H7 -> 285.32287 | I8: =H8*(1-Assumptions!$B$10)+I7 -> 347.1564 | J8: =I8*(1-Assumptions!$B$10)+J7 -> 414.75428 | K8: =J8*(1-Assumptions!$B$10)+K7 -> 488.90755 | ... AL8: =AK8*(1-Assumptions!$B$10)+AL7 -> 3553.6778
A9: Paying fans per active creator | C9: =Assumptions!$B$11+(Assumptions!$B$12-Assumptions!$B$11)*MIN(C4-1,23)/23 -> 12 | D9: =Assumptions!$B$11+(Assumptions!$B$12-Assumptions!$B$11)*MIN(D4-1,23)/23 -> 12.782609 | E9: =Assumptions!$B$11+(Assumptions!$B$12-Assumptions!$B$11)*MIN(E4-1,23)/23 -> 13.565217 | F9: =Assumptions!$B$11+(Assumptions!$B$12-Assumptions!$B$11)*MIN(F4-1,23)/23 -> 14.347826 | G9: =Assumptions!$B$11+(Assumptions!$B$12-Assumptions!$B$11)*MIN(G4-1,23)/23 -> 15.130435 | H9: =Assumptions!$B$11+(Assumptions!$B$12-Assumptions!$B$11)*MIN(H4-1,23)/23 -> 15.913043 | I9: =Assumptions!$B$11+(Assumptions!$B$12-Assumptions!$B$11)*MIN(I4-1,23)/23 -> 16.695652 | J9: =Assumptions!$B$11+(Assumptions!$B$12-Assumptions!$B$11)*MIN(J4-1,23)/23 -> 17.478261 | ... AL9: =Assumptions!$B$11+(Assumptions!$B$12-Assumptions!$B$11)*MIN(AL4-1,23)/23 -> 30
A10: Paying fans | C10: =C8*C9 -> 480 | D10: =D8*D9 -> 1053.287 | E10: =E8*E9 -> 1731.3558 | F10: =F8*F9 -> 2527.6737 | G10: =G8*G9 -> 3457.9353 | H10: =H8*H9 -> 4540.3552 | I10: =I8*I9 -> 5796.0026 | J10: =J8*J9 -> 7249.1834 | ... AL10: =AL8*AL9 -> 106610.33
A11: Fan spend / GMV (excl. VAT) | C11: =C10*Assumptions!$B$13 -> 12000 | D11: =D10*Assumptions!$B$13 -> 26332.174 | E11: =E10*Assumptions!$B$13 -> 43283.896 | F11: =F10*Assumptions!$B$13 -> 63191.843 | G11: =G10*Assumptions!$B$13 -> 86448.383 | H11: =H10*Assumptions!$B$13 -> 113508.88 | I11: =I10*Assumptions!$B$13 -> 144900.06 | J11: =J10*Assumptions!$B$13 -> 181229.59 | ... AL11: =AL10*Assumptions!$B$13 -> 2665258.3
A12: Transactions | C12: =C11/Assumptions!$B$21 -> 800 | D12: =D11/Assumptions!$B$21 -> 1755.4783 | E12: =E11/Assumptions!$B$21 -> 2885.593 | F12: =F11/Assumptions!$B$21 -> 4212.7896 | G12: =G11/Assumptions!$B$21 -> 5763.2255 | H12: =H11/Assumptions!$B$21 -> 7567.2587 | I12: =I11/Assumptions!$B$21 -> 9660.0043 | J12: =J11/Assumptions!$B$21 -> 12081.972 | ... AL12: =AL11/Assumptions!$B$21 -> 177683.89
A13: Revenue
A14: Platform commission | C14: =C11*Assumptions!$B$17 -> 2400 | D14: =D11*Assumptions!$B$17 -> 5266.4348 | E14: =E11*Assumptions!$B$17 -> 8656.7791 | F14: =F11*Assumptions!$B$17 -> 12638.369 | G14: =G11*Assumptions!$B$17 -> 17289.677 | H14: =H11*Assumptions!$B$17 -> 22701.776 | I14: =I11*Assumptions!$B$17 -> 28980.013 | J14: =J11*Assumptions!$B$17 -> 36245.917 | ... AL14: =AL11*Assumptions!$B$17 -> 533051.67
A15: Fan service fee | C15: =C11*Assumptions!$B$18 -> 0 | D15: =D11*Assumptions!$B$18 -> 0 | E15: =E11*Assumptions!$B$18 -> 0 | F15: =F11*Assumptions!$B$18 -> 0 | G15: =G11*Assumptions!$B$18 -> 0 | H15: =H11*Assumptions!$B$18 -> 0 | I15: =I11*Assumptions!$B$18 -> 0 | J15: =J11*Assumptions!$B$18 -> 0 | ... AL15: =AL11*Assumptions!$B$18 -> 0
A16: Less: referral share paid to creators | C16: =-C11*Assumptions!$B$27*Assumptions!$B$17*Assumptions!$B$26 -> -36 | D16: =-D11*Assumptions!$B$27*Assumptions!$B$17*Assumptions!$B$26 -> -78.996522 | E16: =-E11*Assumptions!$B$27*Assumptions!$B$17*Assumptions!$B$26 -> -129.85169 | F16: =-F11*Assumptions!$B$27*Assumptions!$B$17*Assumptions!$B$26 -> -189.57553 | G16: =-G11*Assumptions!$B$27*Assumptions!$B$17*Assumptions!$B$26 -> -259.34515 | H16: =-H11*Assumptions!$B$27*Assumptions!$B$17*Assumptions!$B$26 -> -340.52664 | I16: =-I11*Assumptions!$B$27*Assumptions!$B$17*Assumptions!$B$26 -> -434.70019 | J16: =-J11*Assumptions!$B$27*Assumptions!$B$17*Assumptions!$B$26 -> -543.68876 | ... AL16: =-AL11*Assumptions!$B$27*Assumptions!$B$17*Assumptions!$B$26 -> -7995.775
A17: Creator Pro subscriptions | C17: =C8*Assumptions!$B$36*Assumptions!$B$35 -> 60.8 | D17: =D8*Assumptions!$B$36*Assumptions!$B$35 -> 125.248 | E17: =E8*Assumptions!$B$36*Assumptions!$B$35 -> 194.00064 | F17: =F8*Assumptions!$B$36*Assumptions!$B$35 -> 267.78022 | G17: =G8*Assumptions!$B$36*Assumptions!$B$35 -> 347.38339 | H17: =H8*Assumptions!$B$36*Assumptions!$B$35 -> 433.69076 | I17: =I8*Assumptions!$B$36*Assumptions!$B$35 -> 527.67773 | J17: =J8*Assumptions!$B$36*Assumptions!$B$35 -> 630.4265 | ... AL17: =AL8*Assumptions!$B$36*Assumptions!$B$35 -> 5401.5902
A18: Instant payout fees | C18: =C11*(1-Assumptions!$B$17)*Assumptions!$B$34*Assumptions!$B$33 -> 19.2 | D18: =D11*(1-Assumptions!$B$17)*Assumptions!$B$34*Assumptions!$B$33 -> 42.131478 | E18: =E11*(1-Assumptions!$B$17)*Assumptions!$B$34*Assumptions!$B$33 -> 69.254233 | F18: =F11*(1-Assumptions!$B$17)*Assumptions!$B$34*Assumptions!$B$33 -> 101.10695 | G18: =G11*(1-Assumptions!$B$17)*Assumptions!$B$34*Assumptions!$B$33 -> 138.31741 | H18: =H11*(1-Assumptions!$B$17)*Assumptions!$B$34*Assumptions!$B$33 -> 181.61421 | I18: =I11*(1-Assumptions!$B$17)*Assumptions!$B$34*Assumptions!$B$33 -> 231.8401 | J18: =J11*(1-Assumptions!$B$17)*Assumptions!$B$34*Assumptions!$B$33 -> 289.96734 | ... AL18: =AL11*(1-Assumptions!$B$17)*Assumptions!$B$34*Assumptions!$B$33 -> 4264.4133
A19: Agency / chatter seats | C19: =C8/100*Assumptions!$B$38*Assumptions!$B$37 -> 116 | D19: =D8/100*Assumptions!$B$38*Assumptions!$B$37 -> 238.96 | E19: =E8/100*Assumptions!$B$38*Assumptions!$B$37 -> 370.1328 | F19: =F8/100*Assumptions!$B$38*Assumptions!$B$37 -> 510.89648 | G19: =G8/100*Assumptions!$B$38*Assumptions!$B$37 -> 662.77094 | H19: =H8/100*Assumptions!$B$38*Assumptions!$B$37 -> 827.43632 | I19: =I8/100*Assumptions!$B$38*Assumptions!$B$37 -> 1006.7536 | J19: =J8/100*Assumptions!$B$38*Assumptions!$B$37 -> 1202.7874 | ... AL19: =AL8/100*Assumptions!$B$38*Assumptions!$B$37 -> 10305.666
A20: Featured placements | C20: =C8/100*Assumptions!$B$39 -> 60 | D20: =D8/100*Assumptions!$B$39 -> 123.6 | E20: =E8/100*Assumptions!$B$39 -> 191.448 | F20: =F8/100*Assumptions!$B$39 -> 264.2568 | G20: =G8/100*Assumptions!$B$39 -> 342.81255 | H20: =H8/100*Assumptions!$B$39 -> 427.9843 | I20: =I8/100*Assumptions!$B$39 -> 520.7346 | J20: =J8/100*Assumptions!$B$39 -> 622.13141 | ... AL20: =AL8/100*Assumptions!$B$39 -> 5330.5167
A21: Net revenue | C21: =SUM(C14:C20) -> 2620 | D21: =SUM(D14:D20) -> 5717.3777 | E21: =SUM(E14:E20) -> 9351.7631 | F21: =SUM(F14:F20) -> 13592.834 | G21: =SUM(G14:G20) -> 18521.616 | H21: =SUM(H14:H20) -> 24231.975 | I21: =SUM(I14:I20) -> 30832.319 | J21: =SUM(J14:J20) -> 38447.541 | ... AL21: =SUM(AL14:AL20) -> 550358.08
A22: Variable costs
A23: Card processing | C23: =C11*(1+Assumptions!$B$18)*Assumptions!$B$19+C12*Assumptions!$B$20 -> 1440 | D23: =D11*(1+Assumptions!$B$18)*Assumptions!$B$19+D12*Assumptions!$B$20 -> 3159.8609 | E23: =E11*(1+Assumptions!$B$18)*Assumptions!$B$19+E12*Assumptions!$B$20 -> 5194.0675 | F23: =F11*(1+Assumptions!$B$18)*Assumptions!$B$19+F12*Assumptions!$B$20 -> 7583.0212 | G23: =G11*(1+Assumptions!$B$18)*Assumptions!$B$19+G12*Assumptions!$B$20 -> 10373.806 | H23: =H11*(1+Assumptions!$B$18)*Assumptions!$B$19+H12*Assumptions!$B$20 -> 13621.066 | I23: =I11*(1+Assumptions!$B$18)*Assumptions!$B$19+I12*Assumptions!$B$20 -> 17388.008 | J23: =J11*(1+Assumptions!$B$18)*Assumptions!$B$19+J12*Assumptions!$B$20 -> 21747.55 | ... AL23: =AL11*(1+Assumptions!$B$18)*Assumptions!$B$19+AL12*Assumptions!$B$20 -> 319831
A24: Chargeback fees | C24: =C12*Assumptions!$B$22*Assumptions!$B$23 -> 100 | D24: =D12*Assumptions!$B$22*Assumptions!$B$23 -> 219.43478 | E24: =E12*Assumptions!$B$22*Assumptions!$B$23 -> 360.69913 | F24: =F12*Assumptions!$B$22*Assumptions!$B$23 -> 526.5987 | G24: =G12*Assumptions!$B$22*Assumptions!$B$23 -> 720.40319 | H24: =H12*Assumptions!$B$22*Assumptions!$B$23 -> 945.90733 | I24: =I12*Assumptions!$B$22*Assumptions!$B$23 -> 1207.5005 | J24: =J12*Assumptions!$B$22*Assumptions!$B$23 -> 1510.2465 | ... AL24: =AL12*Assumptions!$B$22*Assumptions!$B$23 -> 22210.486
A25: Refunds borne by platform | C25: =C11*Assumptions!$B$24*Assumptions!$B$25 -> 30 | D25: =D11*Assumptions!$B$24*Assumptions!$B$25 -> 65.830435 | E25: =E11*Assumptions!$B$24*Assumptions!$B$25 -> 108.20974 | F25: =F11*Assumptions!$B$24*Assumptions!$B$25 -> 157.97961 | G25: =G11*Assumptions!$B$24*Assumptions!$B$25 -> 216.12096 | H25: =H11*Assumptions!$B$24*Assumptions!$B$25 -> 283.7722 | I25: =I11*Assumptions!$B$24*Assumptions!$B$25 -> 362.25016 | J25: =J11*Assumptions!$B$24*Assumptions!$B$25 -> 453.07396 | ... AL25: =AL11*Assumptions!$B$24*Assumptions!$B$25 -> 6663.1459
A26: Bandwidth / video delivery | C26: =C10*Assumptions!$B$42 -> 48 | D26: =D10*Assumptions!$B$42 -> 105.3287 | E26: =E10*Assumptions!$B$42 -> 173.13558 | F26: =F10*Assumptions!$B$42 -> 252.76737 | G26: =G10*Assumptions!$B$42 -> 345.79353 | H26: =H10*Assumptions!$B$42 -> 454.03552 | I26: =I10*Assumptions!$B$42 -> 579.60026 | J26: =J10*Assumptions!$B$42 -> 724.91834 | ... AL26: =AL10*Assumptions!$B$42 -> 10661.033
A27: Storage + transcoding | C27: =C8*Assumptions!$B$43 -> 60 | D27: =D8*Assumptions!$B$43 -> 123.6 | E27: =E8*Assumptions!$B$43 -> 191.448 | F27: =F8*Assumptions!$B$43 -> 264.2568 | G27: =G8*Assumptions!$B$43 -> 342.81255 | H27: =H8*Assumptions!$B$43 -> 427.9843 | I27: =I8*Assumptions!$B$43 -> 520.7346 | J27: =J8*Assumptions!$B$43 -> 622.13141 | ... AL27: =AL8*Assumptions!$B$43 -> 5330.5167
A28: Automated moderation | C28: =C8*Assumptions!$B$44 -> 80 | D28: =D8*Assumptions!$B$44 -> 164.8 | E28: =E8*Assumptions!$B$44 -> 255.264 | F28: =F8*Assumptions!$B$44 -> 352.3424 | G28: =G8*Assumptions!$B$44 -> 457.0834 | H28: =H8*Assumptions!$B$44 -> 570.64574 | I28: =I8*Assumptions!$B$44 -> 694.31281 | J28: =J8*Assumptions!$B$44 -> 829.50855 | ... AL28: =AL8*Assumptions!$B$44 -> 7107.3556
A29: Creator identity verification | C29: =C7*Assumptions!$B$45 -> 100 | D29: =D7*Assumptions!$B$45 -> 112 | E29: =E7*Assumptions!$B$45 -> 125.44 | F29: =F7*Assumptions!$B$45 -> 140.4928 | G29: =G7*Assumptions!$B$45 -> 157.35194 | H29: =H7*Assumptions!$B$45 -> 176.23417 | I29: =I7*Assumptions!$B$45 -> 197.38227 | J29: =J7*Assumptions!$B$45 -> 221.06814 | ... AL29: =AL7*Assumptions!$B$45 -> 891.65817
A30: Fan age verification | C30: =C10*Assumptions!$B$46 -> 24 | D30: =D10*Assumptions!$B$46 -> 52.664348 | E30: =E10*Assumptions!$B$46 -> 86.567791 | F30: =F10*Assumptions!$B$46 -> 126.38369 | G30: =G10*Assumptions!$B$46 -> 172.89677 | H30: =H10*Assumptions!$B$46 -> 227.01776 | I30: =I10*Assumptions!$B$46 -> 289.80013 | J30: =J10*Assumptions!$B$46 -> 362.45917 | ... AL30: =AL10*Assumptions!$B$46 -> 5330.5167
A31: Creator payout costs | C31: =C8*Assumptions!$B$48*Assumptions!$B$47 -> 120 | D31: =D8*Assumptions!$B$48*Assumptions!$B$47 -> 247.2 | E31: =E8*Assumptions!$B$48*Assumptions!$B$47 -> 382.896 | F31: =F8*Assumptions!$B$48*Assumptions!$B$47 -> 528.5136 | G31: =G8*Assumptions!$B$48*Assumptions!$B$47 -> 685.62511 | H31: =H8*Assumptions!$B$48*Assumptions!$B$47 -> 855.9686 | I31: =I8*Assumptions!$B$48*Assumptions!$B$47 -> 1041.4692 | J31: =J8*Assumptions!$B$48*Assumptions!$B$47 -> 1244.2628 | ... AL31: =AL8*Assumptions!$B$48*Assumptions!$B$47 -> 10661.033
A32: Email / push | C32: =C10*Assumptions!$B$49 -> 4.8 | D32: =D10*Assumptions!$B$49 -> 10.53287 | E32: =E10*Assumptions!$B$49 -> 17.313558 | F32: =F10*Assumptions!$B$49 -> 25.276737 | G32: =G10*Assumptions!$B$49 -> 34.579353 | H32: =H10*Assumptions!$B$49 -> 45.403552 | I32: =I10*Assumptions!$B$49 -> 57.960026 | J32: =J10*Assumptions!$B$49 -> 72.491834 | ... AL32: =AL10*Assumptions!$B$49 -> 1066.1033
A33: Total variable costs | C33: =SUM(C23:C32) -> 2006.8 | D33: =SUM(D23:D32) -> 4261.252 | E33: =SUM(E23:E32) -> 6895.0413 | F33: =SUM(F23:F32) -> 9957.6329 | G33: =SUM(G23:G32) -> 13506.473 | H33: =SUM(H23:H32) -> 17608.035 | I33: =SUM(I23:I32) -> 22339.018 | J33: =SUM(J23:J32) -> 27787.711 | ... AL33: =SUM(AL23:AL32) -> 389752.85
A34: Contribution | C34: =C21-C33 -> 613.2 | D34: =D21-D33 -> 1456.1257 | E34: =E21-E33 -> 2456.7218 | F34: =F21-F33 -> 3635.2007 | G34: =G21-G33 -> 5015.143 | H34: =H21-H33 -> 6623.9402 | I34: =I21-I33 -> 8493.3009 | J34: =J21-J33 -> 10659.83 | ... AL34: =AL21-AL33 -> 160605.23
A35: Contribution margin (% of net revenue) | C35: =IF(C21=0,0,C34/C21) -> 0.2340458 | D35: =IF(D21=0,0,D34/D21) -> 0.25468419 | E35: =IF(E21=0,0,E34/E21) -> 0.26270146 | F35: =IF(F21=0,0,F34/F21) -> 0.26743509 | G35: =IF(G21=0,0,G34/G21) -> 0.27077243 | H35: =IF(H21=0,0,H34/H21) -> 0.27335536 | I35: =IF(I21=0,0,I34/I21) -> 0.27546747 | J35: =IF(J21=0,0,J34/J21) -> 0.27725648 | ... AL35: =IF(AL21=0,0,AL34/AL21) -> 0.29181952
A36: Net take rate (contribution % of GMV) | C36: =IF(C11=0,0,C34/C11) -> 0.0511 | D36: =IF(D11=0,0,D34/D11) -> 0.055298349 | E36: =IF(E11=0,0,E34/E11) -> 0.056758335 | F36: =IF(F11=0,0,F34/F11) -> 0.057526423 | G36: =IF(G11=0,0,G34/G11) -> 0.05801315 | H36: =IF(H11=0,0,H34/H11) -> 0.058356141 | I36: =IF(I11=0,0,I34/I11) -> 0.058614887 | J36: =IF(J11=0,0,J34/J11) -> 0.05881948 | ... AL36: =IF(AL11=0,0,AL34/AL11) -> 0.060258785
A37: Fixed costs
A38: Team (incl. overhead) | C38: =SUMPRODUCT(Team!$B$5:$B$18,Team!$C$5:$C$18,(Team!$D$5:$D$18<=C4)*1)*(1+Assumptions!$B$52) -> 33465 | D38: =SUMPRODUCT(Team!$B$5:$B$18,Team!$C$5:$C$18,(Team!$D$5:$D$18<=D4)*1)*(1+Assumptions!$B$52) -> 33465 | E38: =SUMPRODUCT(Team!$B$5:$B$18,Team!$C$5:$C$18,(Team!$D$5:$D$18<=E4)*1)*(1+Assumptions!$B$52) -> 33465 | F38: =SUMPRODUCT(Team!$B$5:$B$18,Team!$C$5:$C$18,(Team!$D$5:$D$18<=F4)*1)*(1+Assumptions!$B$52) -> 35190 | G38: =SUMPRODUCT(Team!$B$5:$B$18,Team!$C$5:$C$18,(Team!$D$5:$D$18<=G4)*1)*(1+Assumptions!$B$52) -> 35190 | H38: =SUMPRODUCT(Team!$B$5:$B$18,Team!$C$5:$C$18,(Team!$D$5:$D$18<=H4)*1)*(1+Assumptions!$B$52) -> 35190 | I38: =SUMPRODUCT(Team!$B$5:$B$18,Team!$C$5:$C$18,(Team!$D$5:$D$18<=I4)*1)*(1+Assumptions!$B$52) -> 35190 | J38: =SUMPRODUCT(Team!$B$5:$B$18,Team!$C$5:$C$18,(Team!$D$5:$D$18<=J4)*1)*(1+Assumptions!$B$52) -> 35190 | ... AL38: =SUMPRODUCT(Team!$B$5:$B$18,Team!$C$5:$C$18,(Team!$D$5:$D$18<=AL4)*1)*(1+Assumptions!$B$52) -> 51980
A39: Recurring costs (Fixed Costs tab) | C39: ='Fixed Costs'!$C$34 -> 12305 | D39: ='Fixed Costs'!$C$34 -> 12305 | E39: ='Fixed Costs'!$C$34 -> 12305 | F39: ='Fixed Costs'!$C$34 -> 12305 | G39: ='Fixed Costs'!$C$34 -> 12305 | H39: ='Fixed Costs'!$C$34 -> 12305 | I39: ='Fixed Costs'!$C$34 -> 12305 | J39: ='Fixed Costs'!$C$34 -> 12305 | ... AL39: ='Fixed Costs'!$C$34 -> 12305
A40: Creator acquisition (CAC x new creators) | C40: =C7*Assumptions!$B$14 -> 6000 | D40: =D7*Assumptions!$B$14 -> 6720 | E40: =E7*Assumptions!$B$14 -> 7526.4 | F40: =F7*Assumptions!$B$14 -> 8429.568 | G40: =G7*Assumptions!$B$14 -> 9441.1162 | H40: =H7*Assumptions!$B$14 -> 10574.05 | I40: =I7*Assumptions!$B$14 -> 11842.936 | J40: =J7*Assumptions!$B$14 -> 13264.088 | ... AL40: =AL7*Assumptions!$B$14 -> 53499.49
...

Sheet Unit Economics
A1: Where $100 of fan spend goes
A2: Per-user costs (bandwidth, storage, KYC) are excluded here; they are in the Projection.
A4: Fan service fee used in Model B | B4: 0.08
A6: Line | B6: A: 20% fee, platform pays processing | C6: B: 20% fee + fan service fee | D6: C: creator gets 80% of net after processing | E6: How to read
A7: Listed price paid by fan | B7: 100 | C7: 100 | D7: 100 | E7: Fan-facing price excl. VAT
A8: Fan service fee | B8: 0 | C8: =B7*$B$4 -> 8 | D8: 0 | E8: Model B only
A9: Total charged to fan | B9: =B7+B8 -> 100 | C9: =C7+C8 -> 108 | D9: =D7+D8 -> 100
A10: Card processing | B10: =-B9*Assumptions!$B$19 -> -12 | C10: =-C9*Assumptions!$B$19 -> -12.96 | D10: =-D9*Assumptions!$B$19 -> -12 | E10: Processor rate on everything charged
A11: Paid to creator | B11: =-B7*(1-Assumptions!$B$17) -> -80 | C11: =-C7*(1-Assumptions!$B$17) -> -80 | D11: =-(D9+D10)*(1-Assumptions!$B$17) -> -70.4 | E11: Model C: 80% of the amount after processing
A12: Referral share | B12: =-B7*Assumptions!$B$17*Assumptions!$B$26*Assumptions!$B$27 -> -0.3 | C12: =-C7*Assumptions!$B$17*Assumptions!$B$26*Assumptions!$B$27 -> -0.3 | D12: =-(D9+D10)*Assumptions!$B$17*Assumptions!$B$26*Assumptions!$B$27 -> -0.264 | E12: Blended across referred and non-referred creators
A13: Chargeback fees | B13: =-B9/Assumptions!$B$21*Assumptions!$B$22*Assumptions!$B$23 -> -0.83333333 | C13: =-C9/Assumptions!$B$21*Assumptions!$B$22*Assumptions!$B$23 -> -0.9 | D13: =-D9/Assumptions!$B$21*Assumptions!$B$22*Assumptions!$B$23 -> -0.83333333
A14: Refunds borne by platform | B14: =-B7*Assumptions!$B$24*Assumptions!$B$25 -> -0.25 | C14: =-C7*Assumptions!$B$24*Assumptions!$B$25 -> -0.25 | D14: =-D7*Assumptions!$B$24*Assumptions!$B$25 -> -0.25
A15: Platform keeps | B15: =SUM(B9:B14) -> 6.6166667 | C15: =SUM(C9:C14) -> 13.59 | D15: =SUM(D9:D14) -> 16.252667 | E15: Before people, servers and marketing
A16: Platform keeps, % of fan payment | B16: =B15/B9 -> 0.066166667 | C16: =C15/C9 -> 0.12583333 | D16: =D15/D9 -> 0.16252667
A17: Creator keeps, % of listed price | B17: =-B11/B7 -> 0.8 | C17: =-C11/C7 -> 0.8 | D17: =-D11/D7 -> 0.704 | E17: Creators compare platforms on this
A19: Creator lifetime economics (live scenario, mature month 24+)
A20: Metric | B20: Value | E20: Formula logic
A21: Monthly GMV per active creator | B21: =Assumptions!$B$12*Assumptions!$B$13 -> 750 | E21: Paying fans x ARPPU
A22: Monthly platform contribution per creator | B22: =B21*INDEX(Projection!$C$36:$AL$36,1,36) -> 45.194089 | E22: GMV x net take rate in month 36
A23: Expected creator lifetime (months) | B23: =1/Assumptions!$B$10 -> 16.666667 | E23: 1 / monthly churn
A24: Creator lifetime value (LTV) | B24: =B22*B23 -> 753.23481
A25: Creator acquisition cost (CAC) | B25: =Assumptions!$B$14 -> 150
A26: LTV / CAC | B26: =IF(B25=0,0,B24/B25) -> 5.0215654 | E26: Aim for 3x or more
A27: CAC payback (months) | B27: =IF(B22<=0,0,B25/B22) -> 3.3190181 | E27: Aim for under 12
